<?xml version="1.0"?>
<robot name="wheelchair">
    
    <link name="base_footprint"/>
        <joint name="base_joint" type="fixed">
        <origin xyz="0 0 0.0102" rpy="0 0 1.5708" />
        <parent link="base_footprint"/>
        <child link="base_link" />
    </joint>

    <link name="base_link">
        <visual>
            <geometry>
                <box size="0.5 0.57 0.43"/>
            </geometry>
            <material name="silver">
                <color rgba="0.8 0.8 0.8 1"/>
            </material>
        </visual>
        <collision>
            <geometry>
                <box size="0.5 0.57 0.43"/>
            </geometry>
        </collision>
        <inertial>
            <mass value="1.0"/>
            <inertia ixx="0.015" iyy="0.0375" izz="0.0375" ixy="0" ixz="0" iyz="0"/>
        </inertial>
    </link>


    <link name="block2_seat">
        <visual>
            <geometry>
                <box size="0.5 0.22 0.1"/>
            </geometry>
            <material name="silver"/>
        </visual>
        <collision>
            <geometry>
                <box size="0.5 0.22 0.1"/>
            </geometry>
        </collision>
        <inertial>
            <mass value="1.0"/>
            <inertia ixx="0.015" iyy="0.0375" izz="0.0375" ixy="0" ixz="0" iyz="0"/>
        </inertial>
    </link>

    <joint name="block2_joint" type="fixed">
        <axis xyz="0 0 0"/>
        <parent link="base_link"/>
        <child link="block2_seat"/>
        <origin rpy="0 0 0" xyz="0 -0.175 0.265"/>
    </joint>



    <link name="block3_seat">
        <visual>
            <geometry>
                <box size="0.5 0.26 0.3"/>
            </geometry>
            <material name="silver"/>
        </visual>
        <collision>
            <geometry>
                <box size="0.5 0.26 0.3"/>
            </geometry>
        </collision>
        <inertial>
            <mass value="1.0"/>
            <inertia ixx="0.015" iyy="0.0375" izz="0.0375" ixy="0" ixz="0" iyz="0"/>
        </inertial>
        </link>
    <joint name="block3_joint" type="fixed">
        <axis xyz="0 0 0"/>
        <parent link="base_link"/>
        <child link="block3_seat"/>
        <origin rpy="0 0 0" xyz="0 -0.415 0.165"/>
    </joint>


    <link name="soft_seat">
        <visual>
            <geometry>
                <box size="0.5 0.48 0.03"/>
            </geometry>
            <material name="silver"/>
        </visual>
        <collision>
            <geometry>
                <box size="0.5 0.48 0.03"/>
            </geometry>
        </collision>
        <inertial>
            <mass value="1.0"/>
            <inertia ixx="0.015" iyy="0.0375" izz="0.0375" ixy="0" ixz="0" iyz="0"/>
        </inertial>
    </link>

    <joint name="soft_joint" type="fixed">
        <axis xyz="0 0 0"/>
        <parent link="base_link"/>
        <child link="soft_seat"/>
        <origin rpy="0 0 0" xyz="0 -0.305 0.33"/>
    </joint>


    <link name="back_seat">
        <visual>
        <geometry>
            <box size="0.5 0.02 0.310"/>
        </geometry>
        <material name="silver"/>
        </visual>
        <collision>
            <geometry>
                <box size="0.5 0.02 0.310"/>
            </geometry>
        </collision>
        <inertial>
            <mass value="1.0"/>
            <inertia ixx="0.015" iyy="0.0375" izz="0.0375" ixy="0" ixz="0" iyz="0"/>
        </inertial>
    </link>
    <joint name="back_seat_joint" type="fixed">
        <axis xyz="1 0 0"/>
        <parent link="base_link"/>
        <child link="back_seat"/>
        <origin rpy="0 0 0" xyz="0 -0.065 0.5"/>
    </joint>



<link name="back_pole">
        <visual>
        <geometry>
            <box size="0.05 0.02 1.455"/>
        </geometry>
        <material name="silver"/>
        </visual>
        <collision>
            <geometry>
                <box size="0.5 0.02 0.310"/>
            </geometry>
        </collision>
        <inertial>
            <mass value="1.0"/>
            <inertia ixx="0.015" iyy="0.0375" izz="0.0375" ixy="0" ixz="0" iyz="0"/>
        </inertial>
</link>

<joint name="back_pole_joint" type="fixed">
    <axis xyz="1 0 0"/>
    <parent link="base_link"/>
    <child link="back_pole"/>
    <origin rpy="0 0 0" xyz="0 -0.065 0.7225"/>
</joint>

<link name="rs_lidar_link">
        <visual>
        <geometry>
            <box size="0.05 0.02 0.05"/>
        </geometry>
        <material name="blue" >
        <color rgba="0 0 1 1"/>
        </material>
        </visual>
        <collision>
            <geometry>
                <box size="0.5 0.02 0.310"/>
            </geometry>
        </collision>
        <inertial>
            <mass value="1.0"/>
            <inertia ixx="0.015" iyy="0.0375" izz="0.0375" ixy="0" ixz="0" iyz="0"/>
        </inertial>
    </link>
    
    <joint name="camera_link_joint" type="fixed">
        <axis xyz="1 0 0"/>
        <parent link="back_pole"/>
        <child link="rs_lidar_link"/>
        <origin rpy="0 0.07 -1.5708" xyz="0 0 0.7225"/>
    </joint>





<link name="side_seat">
<visual>
<geometry>
<box size="0.06 0.36 0.18"/>
</geometry>
<material name="silver"/>
</visual>
<collision>
<geometry>
<box size="0.06 0.36 0.18"/>
</geometry>
</collision>
<inertial>
<mass value="1.0"/>
<inertia ixx="0.015" iyy="0.0375" izz="0.0375"
ixy="0" ixz="0" iyz="0"/>
</inertial>
</link>
<joint name="side_seat_joint" type="fixed">
<axis xyz="1 0 0"/>
<parent link="base_link"/>
<child link="side_seat"/>
<origin rpy="0 0 0" xyz="0.25 -0.245 0.435"/>
</joint>


<link name="side_seat_2">
<visual>
<geometry>
<box size="0.06 0.36 0.18"/>
</geometry>
<material name="silver"/>
</visual>
<collision>
<geometry>
<box size="0.06 0.36 0.18"/>
</geometry>
</collision>
<inertial>
<mass value="1.0"/>
<inertia ixx="0.015" iyy="0.0375" izz="0.0375"
ixy="0" ixz="0" iyz="0"/>
</inertial>
</link>
<joint name="side_seat_2_joint" type="fixed">
<axis xyz="1 0 0"/>
<parent link="base_link"/>
<child link="side_seat_2"/>
<origin rpy="0 0 0" xyz="-0.25 -0.245 0.435"/>
</joint>


<link name="front_pole_right">
    <visual>
        <geometry>
            <box size="0.01 0.18 0.01"/>
        </geometry>
        <material name="silver"/>
    </visual>
    <collision>
        <geometry>
            <box size="0.01 0.18 0.01"/>
        </geometry>
    </collision>
    <inertial>
        <mass value="1.0"/>
        <inertia ixx="0.015" iyy="0.0375" izz="0.0375" ixy="0" ixz="0" iyz="0"/>
    </inertial>
</link>
<joint name="front_pole_right_joint" type="fixed">
<axis xyz="1 0 0"/>
<parent link="block3_seat"/>
<child link="front_pole_right"/>
<origin rpy="0 0 0" xyz="-0.25 -0.22 -0.12"/>
</joint>


<link name="front_pole_left">
    <visual>
        <geometry>
            <box size="0.01 0.18 0.01"/>
        </geometry>
        <material name="silver"/>
    </visual>
    <collision>
        <geometry>
            <box size="0.01 0.18 0.01"/>
        </geometry>
    </collision>
    <inertial>
        <mass value="1.0"/>
        <inertia ixx="0.015" iyy="0.0375" izz="0.0375" ixy="0" ixz="0" iyz="0"/>
    </inertial>
</link>

<joint name="front_pole_left_joint" type="fixed">
<axis xyz="1 0 0"/>
<parent link="block3_seat"/>
<child link="front_pole_left"/>
<origin rpy="0 0 0" xyz="0.25 -0.22 -0.12"/>
</joint>


<link name="lidar_panel">
<visual>
<geometry>
<box size="0.5 0.07 0.04"/>
</geometry>
<material name="silver"/>
</visual>
<collision>
<geometry>
<box size="0.5 0.07 0.04"/>
</geometry>
</collision>
<inertial>
<mass value="1.0"/>
<inertia ixx="0.015" iyy="0.0375" izz="0.0375"
ixy="0" ixz="0" iyz="0"/>
</inertial>
</link>
<joint name="lidar_panel_joint" type="fixed">
<axis xyz="1 0 0"/>
<parent link="block3_seat"/>
<child link="lidar_panel"/>
<origin rpy="0 0 0" xyz="0 -0.22 -0.12"/>
</joint>

<link name="laser">
    <visual>
        <geometry>
            <box size="0.1 0.1 0.25"/>
        </geometry>
        <material name="red" >
        <color rgba="1 0 0 1"/>
        </material>
    </visual>

    <inertial>
        <mass value="0.1"/>
        <inertia ixx="5.1458e-5" iyy="5.1458e-5" izz="6.125e-5" ixy="0" ixz="0" iyz="0"/>
    </inertial>
    <collision>
      <geometry>
       <box size="0.1 0.1 0.25"/>
      </geometry>
    </collision>
</link>
<joint name="laser_joint" type="fixed">
<axis xyz="0 0 0"/>
<parent link="lidar_panel"/>
<child link="laser"/>
<origin rpy="0 0 -1.5708" xyz="0 -0.05 -0.145"/>
</joint>


<link name="rp_laser_front">
    <visual>
        <geometry>
            <box size="0.1 0.1 0.25"/>
        </geometry>
        <material name="red" >
        <color rgba="1 0 0 1"/>
        </material>
    </visual>

    <inertial>
        <mass value="0.1"/>
        <inertia ixx="5.1458e-5" iyy="5.1458e-5" izz="6.125e-5" ixy="0" ixz="0" iyz="0"/>
    </inertial>
    <collision>
      <geometry>
       <box size="0.1 0.1 0.25"/>
      </geometry>
    </collision>
</link>
<joint name="rp_laser_front_joint" type="fixed">
<axis xyz="0 0 0"/>
<parent link="lidar_panel"/>
<child link="rp_laser_front"/>
<origin rpy="0 0 -1.57" xyz="0 -0.125 -0.245"/>
</joint>

    <link name="rp_laser_back">
        <visual>
            <geometry>
                <box size="0.05 0.08 0.03"/>
            </geometry>
            <material name="red" >
            <color rgba="1 0 0 1"/>
            </material>
        </visual>
        <collision>
            <geometry>
                <box size="0.05 0.08 0.03"/>
            </geometry>
        </collision>
        <inertial>
            <mass value="1.0"/>
            <inertia ixx="0.015" iyy="0.0375" izz="0.0375" ixy="0" ixz="0" iyz="0"/>
        </inertial>
    </link>

    <joint name="rp_laser_back_joint" type="fixed">
        <axis xyz="0 0 0"/>
        <parent link="base_link"/>
        <child link="rp_laser_back"/>
        <origin rpy="0 0 0" xyz="0.245 0.086 0.325"/>
    </joint>





<link name="front_caster_right">
    <visual>
        <geometry>
            <box size="0.11 0.27 0.27"/>
        </geometry>
        <material name="silver"/>
    </visual>
    <collision>
        <geometry>
            <box size="0.11 0.27 0.27"/>
        </geometry>
    </collision>
    <inertial>
        <mass value="1.0"/>
        <inertia ixx="0.015" iyy="0.0375" izz="0.0375" ixy="0" ixz="0" iyz="0"/>
    </inertial>
</link>
<joint name="front_caster_right_joint" type="continuous">
<axis xyz="0 0 1"/>
<parent link="block3_seat"/>
<child link="front_caster_right"/>
<origin rpy="0 0 0" xyz="-0.265 -0.13 -0.285"/>
</joint>


<link name="front_caster_left">
    <visual>
        <geometry>
            <box size="0.11 0.27 0.27"/>
        </geometry>
        <material name="silver"/>
    </visual>
<collision>
    <geometry>
        <box size="0.11 0.27 0.27"/>
    </geometry>
    </collision>
    <inertial>
        <mass value="1.0"/>
        <inertia ixx="0.015" iyy="0.0375" izz="0.0375" ixy="0" ixz="0" iyz="0"/>
    </inertial>
</link>
<joint name="front_caster_left_joint" type="continuous">
<axis xyz="0 0 1"/>
<parent link="block3_seat"/>
<child link="front_caster_left"/>
<origin rpy="0 0 0" xyz="0.265 -0.13 -0.285"/>
</joint>


<link name="front_wheel_left">
    <visual>
        <geometry>
            <cylinder length="0.09" radius="0.140"/>
        </geometry>
        <material name="black"/>
    </visual>

    <inertial>
        <mass value="0.1"/>
        <inertia ixx="5.1458e-5" iyy="5.1458e-5" izz="6.125e-5" ixy="0" ixz="0" iyz="0"/>
    </inertial>
    <collision>
      <geometry>
        <cylinder length="0.09" radius="0.140"/>
      </geometry>
    </collision>
</link>
<joint name="front_wheel_left_joint" type="continuous">
<axis xyz="0 0 1"/>
<parent link="front_caster_left"/>
<child link="front_wheel_left"/>
<origin rpy="-1.5708 0 1.5708" xyz="0 -0.13 0"/>
</joint>


<link name="front_wheel_right">
<visual>
<geometry>
<cylinder length="0.09" radius="0.140"/>
</geometry>
<material name="black"/>
</visual>
<collision>
      <geometry>
        <cylinder length="0.09" radius="0.140"/>
      </geometry>
</collision>
<inertial>
<mass value="0.1"/>
<inertia ixx="5.1458e-5" iyy="5.1458e-5" izz="6.125e-5" ixy="0" ixz="0" iyz="0"/>
</inertial>
</link>
<joint name="front_wheel_right_joint" type="continuous">
<axis xyz="0 0 1"/>
<parent link="front_caster_right"/>
<child link="front_wheel_right"/>
<origin rpy="-1.5708 0 1.5708" xyz="0 -0.13 0"/>
</joint>


<link name="right_rear_wheel">
<visual>
<geometry>
<cylinder length="0.09" radius="0.225"/>
</geometry>
<material name="black">
<color rgba="0 0 0 1"/>
</material>
</visual>
<collision>
      <geometry>
        <cylinder length="0.09" radius="0.225"/>
      </geometry>
</collision>
<inertial>
<mass value="0.1"/>
<inertia ixx="5.1458e-5" iyy="5.1458e-5" izz="6.125e-5"
ixy="0" ixz="0" iyz="0"/>
</inertial>
</link>
<joint name="right_rear_wheel_joint" type="continuous">
<axis xyz="0 0 -1"/>
<parent link="base_link"/>
<child link="right_rear_wheel"/>
<origin rpy="-1.5708 0 1.5708" xyz="-0.295 0 -0.03"/>
</joint>


<link name="left_rear_wheel">
    <visual>
        <geometry>
            <cylinder length="0.09" radius="0.225"/>
        </geometry>
        <material name="black"/>
    </visual>
    <collision>
      <geometry>
        <cylinder length="0.09" radius="0.225"/>
      </geometry>
    </collision>
    <inertial>  
        <mass value="0.1"/>
        <inertia ixx="5.1458e-5" iyy="5.1458e-5" izz="6.125e-5" ixy="0" ixz="0" iyz="0"/>
    </inertial>
</link>
<joint name="left_rear_wheel_joint" type="continuous">
<axis xyz="0 0 -1"/>
<parent link="base_link"/>
<child link="left_rear_wheel"/>
<origin rpy="-1.5708 0 1.5708" xyz="0.295 0 -0.03"/>
</joint>


</robot>
